Workbook

Sheet 24 QNAS
E1: GOBIERNO DE SINALOA
B5: 12 | C5: Meses | E5: CAT
B6: 24 | C6: Quincenas | E6: 0.8609
B7: 0.03
B8: Saldos Global Fijo
A10: Monto Neto a Prestar | B10: Monto Pagaré | C10: Importe de Descuento | D10: Plazo Mensual | E10: Plazo Knal | F10: Tasa de intrés mensual | G10: Tasa de interés anual | H10: Importe de Intrés | I10: IVA tasa int del crédito | J10: Importe del IVA sobre el interés
A11: 3000 | B11: 4252.8 | C11: 177.2 | D11: 12 | E11: 24 | F11: 0.03 | G11: 0.36 | H11: 1080 | I11: 0.16 | J11: 172.8
A12: 4000 | B12: 5670.4 | C12: 236.27 | D12: 12 | E12: 24 | F12: 0.03 | G12: 0.36 | H12: 1440 | I12: 0.16 | J12: 230.4
A13: 5000 | B13: 7088 | C13: 295.33 | D13: 12 | E13: 24 | F13: 0.03 | G13: 0.36 | H13: 1800 | I13: 0.16 | J13: 288
A14: 6000 | B14: 8505.6 | C14: 354.4 | D14: 12 | E14: 24 | F14: 0.03 | G14: 0.36 | H14: 2160 | I14: 0.16 | J14: 345.6
A15: 7000 | B15: 9923.2 | C15: 413.47 | D15: 12 | E15: 24 | F15: 0.03 | G15: 0.36 | H15: 2520 | I15: 0.16 | J15: 403.2
A16: 8000 | B16: 11340.8 | C16: 472.53 | D16: 12 | E16: 24 | F16: 0.03 | G16: 0.36 | H16: 2880 | I16: 0.16 | J16: 460.8
A17: 9000 | B17: 12758.4 | C17: 531.6 | D17: 12 | E17: 24 | F17: 0.03 | G17: 0.36 | H17: 3240 | I17: 0.16 | J17: 518.4
A18: 10000 | B18: 14176 | C18: 590.67 | D18: 12 | E18: 24 | F18: 0.03 | G18: 0.36 | H18: 3600 | I18: 0.16 | J18: 576
A19: 11000 | B19: 15593.6 | C19: 649.73 | D19: 12 | E19: 24 | F19: 0.03 | G19: 0.36 | H19: 3960 | I19: 0.16 | J19: 633.6
A20: 12000 | B20: 17011.2 | C20: 708.8 | D20: 12 | E20: 24 | F20: 0.03 | G20: 0.36 | H20: 4320 | I20: 0.16 | J20: 691.2
A21: 13000 | B21: 18428.8 | C21: 767.87 | D21: 12 | E21: 24 | F21: 0.03 | G21: 0.36 | H21: 4680 | I21: 0.16 | J21: 748.8
A22: 14000 | B22: 19846.4 | C22: 826.93 | D22: 12 | E22: 24 | F22: 0.03 | G22: 0.36 | H22: 5040 | I22: 0.16 | J22: 806.4
... A308: 300000 | B308: 425280 | C308: 17720 | D308: 12 | E308: 24 | F308: 0.03 | G308: 0.36 | H308: 108000 | I308: 0.16 | J308: 17280

Sheet 36 QNAS
E1: GOBIERNO DE SINALOA
B5: 18 | C5: Meses | E5: CAT
B6: 36 | C6: Quincenas | E6: 0.8298
B7: 0.03
B8: Saldos Global Fijo
A10: Monto Neto a Prestar | B10: Monto Pagaré | C10: Importe de Descuento | D10: Plazo Mensual | E10: Plazo Knal | F10: Tasa de intrés mensual | G10: Tasa de interés anual | H10: Importe de Intrés | I10: IVA tasa int del crédito | J10: Importe del IVA sobre el interés
A11: 3000 | B11: 4879.2 | C11: 135.53 | D11: 18 | E11: 36 | F11: 0.03 | G11: 0.36 | H11: 1620 | I11: 0.16 | J11: 259.2
A12: 4000 | B12: 6505.6 | C12: 180.71 | D12: 18 | E12: 36 | F12: 0.03 | G12: 0.36 | H12: 2160 | I12: 0.16 | J12: 345.6
A13: 5000 | B13: 8132 | C13: 225.89 | D13: 18 | E13: 36 | F13: 0.03 | G13: 0.36 | H13: 2700 | I13: 0.16 | J13: 432
A14: 6000 | B14: 9758.4 | C14: 271.07 | D14: 18 | E14: 36 | F14: 0.03 | G14: 0.36 | H14: 3240 | I14: 0.16 | J14: 518.4
A15: 7000 | B15: 11384.8 | C15: 316.24 | D15: 18 | E15: 36 | F15: 0.03 | G15: 0.36 | H15: 3780 | I15: 0.16 | J15: 604.8
A16: 8000 | B16: 13011.2 | C16: 361.42 | D16: 18 | E16: 36 | F16: 0.03 | G16: 0.36 | H16: 4320 | I16: 0.16 | J16: 691.2
A17: 9000 | B17: 14637.6 | C17: 406.6 | D17: 18 | E17: 36 | F17: 0.03 | G17: 0.36 | H17: 4860 | I17: 0.16 | J17: 777.6
A18: 10000 | B18: 16264 | C18: 451.78 | D18: 18 | E18: 36 | F18: 0.03 | G18: 0.36 | H18: 5400 | I18: 0.16 | J18: 864
A19: 11000 | B19: 17890.4 | C19: 496.96 | D19: 18 | E19: 36 | F19: 0.03 | G19: 0.36 | H19: 5940 | I19: 0.16 | J19: 950.4
A20: 12000 | B20: 19516.8 | C20: 542.13 | D20: 18 | E20: 36 | F20: 0.03 | G20: 0.36 | H20: 6480 | I20: 0.16 | J20: 1036.8
A21: 13000 | B21: 21143.2 | C21: 587.31 | D21: 18 | E21: 36 | F21: 0.03 | G21: 0.36 | H21: 7020 | I21: 0.16 | J21: 1123.2
A22: 14000 | B22: 22769.6 | C22: 632.49 | D22: 18 | E22: 36 | F22: 0.03 | G22: 0.36 | H22: 7560 | I22: 0.16 | J22: 1209.6
... A308: 300000 | B308: 487920 | C308: 13553.33 | D308: 18 | E308: 36 | F308: 0.03 | G308: 0.36 | H308: 162000 | I308: 0.16 | J308: 25920

Sheet 48 QNAS
E1: GOBIERNO DE SINALOA
B5: 24 | C5: Meses | E5: CAT
B6: 48 | C6: Quincenas | E6: 0.7983
B7: 0.03
B8: Saldos Global Fijo
A10: Monto Neto a Prestar | B10: Monto Pagaré | C10: Importe de Descuento | D10: Plazo Mensual | E10: Plazo Knal | F10: Tasa de intrés mensual | G10: Tasa de interés anual | H10: Importe de Intrés | I10: IVA tasa int del crédito | J10: Importe del IVA sobre el interés
A11: 3000 | B11: 5505.6 | C11: 114.7 | D11: 24 | E11: 48 | F11: 0.03 | G11: 0.36 | H11: 2160 | I11: 0.16 | J11: 345.6
A12: 4000 | B12: 7340.8 | C12: 152.93 | D12: 24 | E12: 48 | F12: 0.03 | G12: 0.36 | H12: 2880 | I12: 0.16 | J12: 460.8
A13: 5000 | B13: 9176 | C13: 191.17 | D13: 24 | E13: 48 | F13: 0.03 | G13: 0.36 | H13: 3600 | I13: 0.16 | J13: 576
A14: 6000 | B14: 11011.2 | C14: 229.4 | D14: 24 | E14: 48 | F14: 0.03 | G14: 0.36 | H14: 4320 | I14: 0.16 | J14: 691.2
A15: 7000 | B15: 12846.4 | C15: 267.63 | D15: 24 | E15: 48 | F15: 0.03 | G15: 0.36 | H15: 5040 | I15: 0.16 | J15: 806.4
A16: 8000 | B16: 14681.6 | C16: 305.87 | D16: 24 | E16: 48 | F16: 0.03 | G16: 0.36 | H16: 5760 | I16: 0.16 | J16: 921.6
A17: 9000 | B17: 16516.8 | C17: 344.1 | D17: 24 | E17: 48 | F17: 0.03 | G17: 0.36 | H17: 6480 | I17: 0.16 | J17: 1036.8
A18: 10000 | B18: 18352 | C18: 382.33 | D18: 24 | E18: 48 | F18: 0.03 | G18: 0.36 | H18: 7200 | I18: 0.16 | J18: 1152
A19: 11000 | B19: 20187.2 | C19: 420.57 | D19: 24 | E19: 48 | F19: 0.03 | G19: 0.36 | H19: 7920 | I19: 0.16 | J19: 1267.2
A20: 12000 | B20: 22022.4 | C20: 458.8 | D20: 24 | E20: 48 | F20: 0.03 | G20: 0.36 | H20: 8640 | I20: 0.16 | J20: 1382.4
A21: 13000 | B21: 23857.6 | C21: 497.03 | D21: 24 | E21: 48 | F21: 0.03 | G21: 0.36 | H21: 9360 | I21: 0.16 | J21: 1497.6
A22: 14000 | B22: 25692.8 | C22: 535.27 | D22: 24 | E22: 48 | F22: 0.03 | G22: 0.36 | H22: 10080 | I22: 0.16 | J22: 1612.8
... A308: 300000 | B308: 550560 | C308: 11470 | D308: 24 | E308: 48 | F308: 0.03 | G308: 0.36 | H308: 216000 | I308: 0.16 | J308: 34560

Sheet 72 QNAS
E1: GOBIERNO DE SINALOA
B5: 36 | C5: Meses | E5: CAT
B6: 72 | C6: Quincenas | E6: 0.7439
B7: 0.03
B8: Saldos Global Fijo
A10: Monto Neto a Prestar | B10: Monto Pagaré | C10: Importe de Descuento | D10: Plazo Mensual | E10: Plazo Knal | F10: Tasa de intrés mensual | G10: Tasa de interés anual | H10: Importe de Intrés | I10: IVA tasa int del crédito | J10: Importe del IVA sobre el interés
A11: 3000 | B11: 6758.4 | C11: 93.87 | D11: 36 | E11: 72 | F11: 0.03 | G11: 0.36 | H11: 3240 | I11: 0.16 | J11: 518.4
A12: 4000 | B12: 9011.2 | C12: 125.16 | D12: 36 | E12: 72 | F12: 0.03 | G12: 0.36 | H12: 4320 | I12: 0.16 | J12: 691.2
A13: 5000 | B13: 11264 | C13: 156.44 | D13: 36 | E13: 72 | F13: 0.03 | G13: 0.36 | H13: 5400 | I13: 0.16 | J13: 864
A14: 6000 | B14: 13516.8 | C14: 187.73 | D14: 36 | E14: 72 | F14: 0.03 | G14: 0.36 | H14: 6480 | I14: 0.16 | J14: 1036.8
A15: 7000 | B15: 15769.6 | C15: 219.02 | D15: 36 | E15: 72 | F15: 0.03 | G15: 0.36 | H15: 7560 | I15: 0.16 | J15: 1209.6
A16: 8000 | B16: 18022.4 | C16: 250.31 | D16: 36 | E16: 72 | F16: 0.03 | G16: 0.36 | H16: 8640 | I16: 0.16 | J16: 1382.4
A17: 9000 | B17: 20275.2 | C17: 281.6 | D17: 36 | E17: 72 | F17: 0.03 | G17: 0.36 | H17: 9720 | I17: 0.16 | J17: 1555.2
A18: 10000 | B18: 22528 | C18: 312.89 | D18: 36 | E18: 72 | F18: 0.03 | G18: 0.36 | H18: 10800 | I18: 0.16 | J18: 1728
A19: 11000 | B19: 24780.8 | C19: 344.18 | D19: 36 | E19: 72 | F19: 0.03 | G19: 0.36 | H19: 11880 | I19: 0.16 | J19: 1900.8
A20: 12000 | B20: 27033.6 | C20: 375.47 | D20: 36 | E20: 72 | F20: 0.03 | G20: 0.36 | H20: 12960 | I20: 0.16 | J20: 2073.6
A21: 13000 | B21: 29286.4 | C21: 406.76 | D21: 36 | E21: 72 | F21: 0.03 | G21: 0.36 | H21: 14040 | I21: 0.16 | J21: 2246.4
A22: 14000 | B22: 31539.2 | C22: 438.04 | D22: 36 | E22: 72 | F22: 0.03 | G22: 0.36 | H22: 15120 | I22: 0.16 | J22: 2419.2
... A308: 300000 | B308: 675840 | C308: 9386.67 | D308: 36 | E308: 72 | F308: 0.03 | G308: 0.36 | H308: 324000 | I308: 0.16 | J308: 51840

Sheet 96 QNAS
E1: GOBIERNO DE SINALOA
B5: 48 | C5: Meses | E5: CAT
B6: 96 | C6: Quincenas | E6: 0.701
B7: 0.03 | D7: 0.03
B8: Saldos Global Fijo
A10: Monto Neto a Prestar | B10: Monto Pagaré | C10: Importe de Descuento | D10: Plazo Mensual | E10: Plazo Knal | F10: Tasa de intrés mensual | G10: Tasa de interés anual | H10: Importe de Intrés | I10: IVA tasa int del crédito | J10: Importe del IVA sobre el interés
A11: 3000 | B11: 8011.2 | C11: 83.45 | D11: 48 | E11: 96 | F11: 0.03 | G11: 0.36 | H11: 4320 | I11: 0.16 | J11: 691.2
A12: 4000 | B12: 10681.6 | C12: 111.26667 | D12: 48 | E12: 96 | F12: 0.03 | G12: 0.36 | H12: 5760 | I12: 0.16 | J12: 921.6
A13: 5000 | B13: 13352 | C13: 139.08333 | D13: 48 | E13: 96 | F13: 0.03 | G13: 0.36 | H13: 7200 | I13: 0.16 | J13: 1152
A14: 6000 | B14: 16022.4 | C14: 166.9 | D14: 48 | E14: 96 | F14: 0.03 | G14: 0.36 | H14: 8640 | I14: 0.16 | J14: 1382.4
A15: 7000 | B15: 18692.8 | C15: 194.71667 | D15: 48 | E15: 96 | F15: 0.03 | G15: 0.36 | H15: 10080 | I15: 0.16 | J15: 1612.8
A16: 8000 | B16: 21363.2 | C16: 222.53333 | D16: 48 | E16: 96 | F16: 0.03 | G16: 0.36 | H16: 11520 | I16: 0.16 | J16: 1843.2
A17: 9000 | B17: 24033.6 | C17: 250.35 | D17: 48 | E17: 96 | F17: 0.03 | G17: 0.36 | H17: 12960 | I17: 0.16 | J17: 2073.6
A18: 10000 | B18: 26704 | C18: 278.16667 | D18: 48 | E18: 96 | F18: 0.03 | G18: 0.36 | H18: 14400 | I18: 0.16 | J18: 2304
A19: 11000 | B19: 29374.4 | C19: 305.98333 | D19: 48 | E19: 96 | F19: 0.03 | G19: 0.36 | H19: 15840 | I19: 0.16 | J19: 2534.4
A20: 12000 | B20: 32044.8 | C20: 333.8 | D20: 48 | E20: 96 | F20: 0.03 | G20: 0.36 | H20: 17280 | I20: 0.16 | J20: 2764.8
A21: 13000 | B21: 34715.2 | C21: 361.61667 | D21: 48 | E21: 96 | F21: 0.03 | G21: 0.36 | H21: 18720 | I21: 0.16 | J21: 2995.2
A22: 14000 | B22: 37385.6 | C22: 389.43333 | D22: 48 | E22: 96 | F22: 0.03 | G22: 0.36 | H22: 20160 | I22: 0.16 | J22: 3225.6
... A308: 300000 | B308: 801120 | C308: 8345 | D308: 48 | E308: 96 | F308: 0.03 | G308: 0.36 | H308: 432000 | I308: 0.16 | J308: 69120

Sheet 120 QNAS
E1: GOBIERNO DE SINALOA
B5: =(B6*15)/30 -> 60 | C5: Meses | E5: CAT
B6: 120 | C6: Quincenas | E6: 0.667
B7: 0.03 | D7: 0.03
B8: Saldos Global Fijo
A10: Monto Neto a Prestar | B10: Monto Pagaré | C10: Importe de Descuento | D10: Plazo Mensual | E10: Plazo Knal | F10: Tasa de intrés mensual | G10: Tasa de interés anual | H10: Importe de Intrés | I10: IVA tasa int del crédito | J10: Importe del IVA sobre el interés
A11: 3000 | B11: 9264 | C11: 77.2 | D11: 60 | E11: 120 | F11: 0.03 | G11: 0.36 | H11: 5400 | I11: 0.16 | J11: 864
A12: 4000 | B12: 12352 | C12: 102.93333 | D12: 60 | E12: 120 | F12: 0.03 | G12: 0.36 | H12: 7200 | I12: 0.16 | J12: 1152
A13: 5000 | B13: 15440 | C13: 128.66667 | D13: 60 | E13: 120 | F13: 0.03 | G13: 0.36 | H13: 9000 | I13: 0.16 | J13: 1440
A14: 6000 | B14: 18528 | C14: 154.4 | D14: 60 | E14: 120 | F14: 0.03 | G14: 0.36 | H14: 10800 | I14: 0.16 | J14: 1728
A15: 7000 | B15: 21616 | C15: 180.13333 | D15: 60 | E15: 120 | F15: 0.03 | G15: 0.36 | H15: 12600 | I15: 0.16 | J15: 2016
A16: 8000 | B16: 24704 | C16: 205.86667 | D16: 60 | E16: 120 | F16: 0.03 | G16: 0.36 | H16: 14400 | I16: 0.16 | J16: 2304
A17: 9000 | B17: 27792 | C17: 231.6 | D17: 60 | E17: 120 | F17: 0.03 | G17: 0.36 | H17: 16200 | I17: 0.16 | J17: 2592
A18: 10000 | B18: 30880 | C18: 257.33333 | D18: 60 | E18: 120 | F18: 0.03 | G18: 0.36 | H18: 18000 | I18: 0.16 | J18: 2880
A19: 11000 | B19: 33968 | C19: 283.06667 | D19: 60 | E19: 120 | F19: 0.03 | G19: 0.36 | H19: 19800 | I19: 0.16 | J19: 3168
A20: 12000 | B20: 37056 | C20: 308.8 | D20: 60 | E20: 120 | F20: 0.03 | G20: 0.36 | H20: 21600 | I20: 0.16 | J20: 3456
A21: 13000 | B21: 40144 | C21: 334.53333 | D21: 60 | E21: 120 | F21: 0.03 | G21: 0.36 | H21: 23400 | I21: 0.16 | J21: 3744
A22: 14000 | B22: 43232 | C22: 360.26667 | D22: 60 | E22: 120 | F22: 0.03 | G22: 0.36 | H22: 25200 | I22: 0.16 | J22: 4032
... A308: 300000 | B308: 926400 | C308: 7720 | D308: 60 | E308: 120 | F308: 0.03 | G308: 0.36 | H308: 540000 | I308: 0.16 | J308: 86400

Sheet tablas Guia
A1: Tasa Anual | B1: ='72 QNAS'!#REF! -> #REF! | D1: ='48 QNAS'!#REF! -> #REF! | F1: ='36 QNAS'!#REF! -> #REF! | H1: ='24 QNAS'!#REF! -> #REF! | K1: Tasa Anual | L1: =B1 -> #REF! | N1: =D1 -> #REF! | P1: =F1 -> #REF! | R1: =H1 -> #REF!
A2: Tasa Mensual | B2: =B1/12 -> #REF! | D2: =D1/12 -> #REF! | F2: =F1/12 -> #REF! | H2: =H1/12 -> #REF! | K2: Tasa Mensual | L2: =B2 -> #REF! | N2: =D2 -> #REF! | P2: =F2 -> #REF! | R2: =H2 -> #REF!
A3: CAT | B3: 0.7439 | D3: 0.7983 | F3: 0.8298 | H3: 0.8609 | K3: CAT | L3: =B3 -> 0.7439 | N3: =D3 -> 0.7983 | P3: =F3 -> 0.8298 | R3: =H3 -> 0.8609
A4: Monto a Dispersar | B4: 72 Quincenas | D4: 48 Quincenas | F4: 36 Quincenas | H4: 24 Quincenas | K4: Monto a Dispersar | L4: =B4 -> 72 Quincenas | N4: =D4 -> 48 Quincenas | P4: =F4 -> 36 Quincenas | R4: =H4 -> 24 Quincenas
B5: Descuento | C5: Total a pagar | D5: Descuento | E5: Total a pagar | F5: Descuento | G5: Total a pagar | H5: Descuento | I5: Total a pagar | L5: Descuento | M5: Total a pagar | N5: Descuento | O5: Total a pagar | P5: Descuento | Q5: Total a pagar | R5: Descuento | S5: Total a pagar
A6: 2000 | B6: ='72 QNAS'!#REF! -> #REF! | C6: ='72 QNAS'!#REF! -> #REF! | D6: ='48 QNAS'!#REF! -> #REF! | E6: ='48 QNAS'!#REF! -> #REF! | F6: ='36 QNAS'!#REF! -> #REF! | G6: ='36 QNAS'!#REF! -> #REF! | H6: ='24 QNAS'!#REF! -> #REF! | I6: ='24 QNAS'!#REF! -> #REF! | K6: 52000 | L6: ='72 QNAS'!C60 -> 1627.02 | M6: ='72 QNAS'!B60 -> 117145.6 | N6: ='48 QNAS'!C60 -> 1988.13 | O6: ='48 QNAS'!B60 -> 95430.4 | P6: ='36 QNAS'!C60 -> 2349.24 | Q6: ='36 QNAS'!B60 -> 84572.8 | R6: ='24 QNAS'!C60 -> 3071.47 | S6: ='24 QNAS'!B60 -> 73715.2
A7: 3000 | B7: ='72 QNAS'!C11 -> 93.87 | C7: ='72 QNAS'!B11 -> 6758.4 | D7: ='48 QNAS'!C11 -> 114.7 | E7: ='48 QNAS'!B11 -> 5505.6 | F7: ='36 QNAS'!C11 -> 135.53 | G7: ='36 QNAS'!B11 -> 4879.2 | H7: ='24 QNAS'!C11 -> 177.2 | I7: ='24 QNAS'!B11 -> 4252.8 | K7: 53000 | L7: ='72 QNAS'!C61 -> 1658.31 | M7: ='72 QNAS'!B61 -> 119398.4 | N7: ='48 QNAS'!C61 -> 2026.37 | O7: ='48 QNAS'!B61 -> 97265.6 | P7: ='36 QNAS'!C61 -> 2394.42 | Q7: ='36 QNAS'!B61 -> 86199.2 | R7: ='24 QNAS'!C61 -> 3130.53 | S7: ='24 QNAS'!B61 -> 75132.8
A8: 4000 | B8: ='72 QNAS'!C12 -> 125.16 | C8: ='72 QNAS'!B12 -> 9011.2 | D8: ='48 QNAS'!C12 -> 152.93 | E8: ='48 QNAS'!B12 -> 7340.8 | F8: ='36 QNAS'!C12 -> 180.71 | G8: ='36 QNAS'!B12 -> 6505.6 | H8: ='24 QNAS'!C12 -> 236.27 | I8: ='24 QNAS'!B12 -> 5670.4 | K8: 54000 | L8: ='72 QNAS'!C62 -> 1689.6 | M8: ='72 QNAS'!B62 -> 121651.2 | N8: ='48 QNAS'!C62 -> 2064.6 | O8: ='48 QNAS'!B62 -> 99100.8 | P8: ='36 QNAS'!C62 -> 2439.6 | Q8: ='36 QNAS'!B62 -> 87825.6 | R8: ='24 QNAS'!C62 -> 3189.6 | S8: ='24 QNAS'!B62 -> 76550.4
A9: 5000 | B9: ='72 QNAS'!C13 -> 156.44 | C9: ='72 QNAS'!B13 -> 11264 | D9: ='48 QNAS'!C13 -> 191.17 | E9: ='48 QNAS'!B13 -> 9176 | F9: ='36 QNAS'!C13 -> 225.89 | G9: ='36 QNAS'!B13 -> 8132 | H9: ='24 QNAS'!C13 -> 295.33 | I9: ='24 QNAS'!B13 -> 7088 | K9: 55000 | L9: ='72 QNAS'!C63 -> 1720.89 | M9: ='72 QNAS'!B63 -> 123904 | N9: ='48 QNAS'!C63 -> 2102.83 | O9: ='48 QNAS'!B63 -> 100936 | P9: ='36 QNAS'!C63 -> 2484.78 | Q9: ='36 QNAS'!B63 -> 89452 | R9: ='24 QNAS'!C63 -> 3248.67 | S9: ='24 QNAS'!B63 -> 77968
A10: 6000 | B10: ='72 QNAS'!C14 -> 187.73 | C10: ='72 QNAS'!B14 -> 13516.8 | D10: ='48 QNAS'!C14 -> 229.4 | E10: ='48 QNAS'!B14 -> 11011.2 | F10: ='36 QNAS'!C14 -> 271.07 | G10: ='36 QNAS'!B14 -> 9758.4 | H10: ='24 QNAS'!C14 -> 354.4 | I10: ='24 QNAS'!B14 -> 8505.6 | K10: 56000 | L10: ='72 QNAS'!C64 -> 1752.18 | M10: ='72 QNAS'!B64 -> 126156.8 | N10: ='48 QNAS'!C64 -> 2141.07 | O10: ='48 QNAS'!B64 -> 102771.2 | P10: ='36 QNAS'!C64 -> 2529.96 | Q10: ='36 QNAS'!B64 -> 91078.4 | R10: ='24 QNAS'!C64 -> 3307.73 | S10: ='24 QNAS'!B64 -> 79385.6
A11: 7000 | B11: ='72 QNAS'!C15 -> 219.02 | C11: ='72 QNAS'!B15 -> 15769.6 | D11: ='48 QNAS'!C15 -> 267.63 | E11: ='48 QNAS'!B15 -> 12846.4 | F11: ='36 QNAS'!C15 -> 316.24 | G11: ='36 QNAS'!B15 -> 11384.8 | H11: ='24 QNAS'!C15 -> 413.47 | I11: ='24 QNAS'!B15 -> 9923.2 | K11: 57000 | L11: ='72 QNAS'!C65 -> 1783.47 | M11: ='72 QNAS'!B65 -> 128409.6 | N11: ='48 QNAS'!C65 -> 2179.3 | O11: ='48 QNAS'!B65 -> 104606.4 | P11: ='36 QNAS'!C65 -> 2575.13 | Q11: ='36 QNAS'!B65 -> 92704.8 | R11: ='24 QNAS'!C65 -> 3366.8 | S11: ='24 QNAS'!B65 -> 80803.2
A12: 8000 | B12: ='72 QNAS'!C16 -> 250.31 | C12: ='72 QNAS'!B16 -> 18022.4 | D12: ='48 QNAS'!C16 -> 305.87 | E12: ='48 QNAS'!B16 -> 14681.6 | F12: ='36 QNAS'!C16 -> 361.42 | G12: ='36 QNAS'!B16 -> 13011.2 | H12: ='24 QNAS'!C16 -> 472.53 | I12: ='24 QNAS'!B16 -> 11340.8 | K12: 58000 | L12: ='72 QNAS'!C66 -> 1814.76 | M12: ='72 QNAS'!B66 -> 130662.4 | N12: ='48 QNAS'!C66 -> 2217.53 | O12: ='48 QNAS'!B66 -> 106441.6 | P12: ='36 QNAS'!C66 -> 2620.31 | Q12: ='36 QNAS'!B66 -> 94331.2 | R12: ='24 QNAS'!C66 -> 3425.87 | S12: ='24 QNAS'!B66 -> 82220.8
A13: 9000 | B13: ='72 QNAS'!C17 -> 281.6 | C13: ='72 QNAS'!B17 -> 20275.2 | D13: ='48 QNAS'!C17 -> 344.1 | E13: ='48 QNAS'!B17 -> 16516.8 | F13: ='36 QNAS'!C17 -> 406.6 | G13: ='36 QNAS'!B17 -> 14637.6 | H13: ='24 QNAS'!C17 -> 531.6 | I13: ='24 QNAS'!B17 -> 12758.4 | K13: 59000 | L13: ='72 QNAS'!C67 -> 1846.04 | M13: ='72 QNAS'!B67 -> 132915.2 | N13: ='48 QNAS'!C67 -> 2255.77 | O13: ='48 QNAS'!B67 -> 108276.8 | P13: ='36 QNAS'!C67 -> 2665.49 | Q13: ='36 QNAS'!B67 -> 95957.6 | R13: ='24 QNAS'!C67 -> 3484.93 | S13: ='24 QNAS'!B67 -> 83638.4
A14: 10000 | B14: ='72 QNAS'!C18 -> 312.89 | C14: ='72 QNAS'!B18 -> 22528 | D14: ='48 QNAS'!C18 -> 382.33 | E14: ='48 QNAS'!B18 -> 18352 | F14: ='36 QNAS'!C18 -> 451.78 | G14: ='36 QNAS'!B18 -> 16264 | H14: ='24 QNAS'!C18 -> 590.67 | I14: ='24 QNAS'!B18 -> 14176 | K14: 60000 | L14: ='72 QNAS'!C68 -> 1877.33 | M14: ='72 QNAS'!B68 -> 135168 | N14: ='48 QNAS'!C68 -> 2294 | O14: ='48 QNAS'!B68 -> 110112 | P14: ='36 QNAS'!C68 -> 2710.67 | Q14: ='36 QNAS'!B68 -> 97584 | R14: ='24 QNAS'!C68 -> 3544 | S14: ='24 QNAS'!B68 -> 85056
A15: 11000 | B15: ='72 QNAS'!C19 -> 344.18 | C15: ='72 QNAS'!B19 -> 24780.8 | D15: ='48 QNAS'!C19 -> 420.57 | E15: ='48 QNAS'!B19 -> 20187.2 | F15: ='36 QNAS'!C19 -> 496.96 | G15: ='36 QNAS'!B19 -> 17890.4 | H15: ='24 QNAS'!C19 -> 649.73 | I15: ='24 QNAS'!B19 -> 15593.6 | K15: 61000 | L15: ='72 QNAS'!C69 -> 1908.62 | M15: ='72 QNAS'!B69 -> 137420.8 | N15: ='48 QNAS'!C69 -> 2332.23 | O15: ='48 QNAS'!B69 -> 111947.2 | P15: ='36 QNAS'!C69 -> 2755.84 | Q15: ='36 QNAS'!B69 -> 99210.4 | R15: ='24 QNAS'!C69 -> 3603.07 | S15: ='24 QNAS'!B69 -> 86473.6
A16: 12000 | B16: ='72 QNAS'!C20 -> 375.47 | C16: ='72 QNAS'!B20 -> 27033.6 | D16: ='48 QNAS'!C20 -> 458.8 | E16: ='48 QNAS'!B20 -> 22022.4 | F16: ='36 QNAS'!C20 -> 542.13 | G16: ='36 QNAS'!B20 -> 19516.8 | H16: ='24 QNAS'!C20 -> 708.8 | I16: ='24 QNAS'!B20 -> 17011.2 | K16: 62000 | L16: ='72 QNAS'!C70 -> 1939.91 | M16: ='72 QNAS'!B70 -> 139673.6 | N16: ='48 QNAS'!C70 -> 2370.47 | O16: ='48 QNAS'!B70 -> 113782.4 | P16: ='36 QNAS'!C70 -> 2801.02 | Q16: ='36 QNAS'!B70 -> 100836.8 | R16: ='24 QNAS'!C70 -> 3662.13 | S16: ='24 QNAS'!B70 -> 87891.2
A17: 13000 | B17: ='72 QNAS'!C21 -> 406.76 | C17: ='72 QNAS'!B21 -> 29286.4 | D17: ='48 QNAS'!C21 -> 497.03 | E17: ='48 QNAS'!B21 -> 23857.6 | F17: ='36 QNAS'!C21 -> 587.31 | G17: ='36 QNAS'!B21 -> 21143.2 | H17: ='24 QNAS'!C21 -> 767.87 | I17: ='24 QNAS'!B21 -> 18428.8 | K17: 63000 | L17: ='72 QNAS'!C71 -> 1971.2 | M17: ='72 QNAS'!B71 -> 141926.4 | N17: ='48 QNAS'!C71 -> 2408.7 | O17: ='48 QNAS'!B71 -> 115617.6 | P17: ='36 QNAS'!C71 -> 2846.2 | Q17: ='36 QNAS'!B71 -> 102463.2 | R17: ='24 QNAS'!C71 -> 3721.2 | S17: ='24 QNAS'!B71 -> 89308.8
A18: 14000 | B18: ='72 QNAS'!C22 -> 438.04 | C18: ='72 QNAS'!B22 -> 31539.2 | D18: ='48 QNAS'!C22 -> 535.27 | E18: ='48 QNAS'!B22 -> 25692.8 | F18: ='36 QNAS'!C22 -> 632.49 | G18: ='36 QNAS'!B22 -> 22769.6 | H18: ='24 QNAS'!C22 -> 826.93 | I18: ='24 QNAS'!B22 -> 19846.4 | K18: 64000 | L18: ='72 QNAS'!C72 -> 2002.49 | M18: ='72 QNAS'!B72 -> 144179.2 | N18: ='48 QNAS'!C72 -> 2446.93 | O18: ='48 QNAS'!B72 -> 117452.8 | P18: ='36 QNAS'!C72 -> 2891.38 | Q18: ='36 QNAS'!B72 -> 104089.6 | R18: ='24 QNAS'!C72 -> 3780.27 | S18: ='24 QNAS'!B72 -> 90726.4
... A55: 51000 | B55: ='72 QNAS'!C59 -> 1595.73 | C55: ='72 QNAS'!B59 -> 114892.8 | D55: ='48 QNAS'!C59 -> 1949.9 | E55: ='48 QNAS'!B59 -> 93595.2 | F55: ='36 QNAS'!C59 -> 2304.07 | G55: ='36 QNAS'!B59 -> 82946.4 | H55: ='24 QNAS'!C59 -> 3012.4 | I55: ='24 QNAS'!B59 -> 72297.6 | K55: 101000 | L55: ='72 QNAS'!C109 -> 3160.18 | M55: ='72 QNAS'!B109 -> 227532.8 | N55: ='48 QNAS'!C109 -> 3861.57 | O55: ='48 QNAS'!B109 -> 185355.2 | P55: ='36 QNAS'!C109 -> 4562.96 | Q55: ='36 QNAS'!B109 -> 164266.4 | R55: ='24 QNAS'!C109 -> 5965.73 | S55: ='24 QNAS'!B109 -> 143177.6
A58: Tasa Anual | B58: =B1 -> #REF! | D58: =D1 -> #REF! | F58: =F1 -> #REF! | H58: =H1 -> #REF! | K58: Tasa Anual | L58: =L1 -> #REF! | N58: =N1 -> #REF! | P58: =P1 -> #REF! | R58: =R1 -> #REF!
A59: Tasa Mensual | B59: =B2 -> #REF! | D59: =D2 -> #REF! | F59: =F2 -> #REF! | H59: =H2 -> #REF! | K59: Tasa Mensual | L59: =L2 -> #REF! | N59: =N2 -> #REF! | P59: =P2 -> #REF! | R59: =R2 -> #REF!
A60: CAT | B60: =B3 -> 0.7439 | D60: =D3 -> 0.7983 | F60: =F3 -> 0.8298 | H60: =H3 -> 0.8609 | K60: CAT | L60: =L3 -> 0.7439 | N60: =N3 -> 0.7983 | P60: =P3 -> 0.8298 | R60: =R3 -> 0.8609
A61: Monto a Dispersar | B61: =B4 -> 72 Quincenas | D61: =D4 -> 48 Quincenas | F61: =F4 -> 36 Quincenas | H61: =H4 -> 24 Quincenas | K61: Monto a Dispersar | L61: =B4 -> 72 Quincenas | N61: =D4 -> 48 Quincenas | P61: =F4 -> 36 Quincenas | R61: =H4 -> 24 Quincenas
B62: Descuento | C62: Total a pagar | D62: Descuento | E62: Total a pagar | F62: Descuento | G62: Total a pagar | H62: Descuento | I62: Total a pagar | L62: Descuento | M62: Total a pagar | N62: Descuento | O62: Total a pagar | P62: Descuento | Q62: Total a pagar | R62: Descuento | S62: Total a pagar
A63: 102000 | B63: ='72 QNAS'!C110 -> 3191.47 | C63: ='72 QNAS'!B110 -> 229785.6 | D63: ='48 QNAS'!C110 -> 3899.8 | E63: ='48 QNAS'!B110 -> 187190.4 | F63: ='36 QNAS'!C110 -> 4608.13 | G63: ='36 QNAS'!B110 -> 165892.8 | H63: ='24 QNAS'!C110 -> 6024.8 | I63: ='24 QNAS'!B110 -> 144595.2 | K63: 152000 | L63: ='72 QNAS'!C160 -> 4755.91 | M63: ='72 QNAS'!B160 -> 342425.6 | N63: ='48 QNAS'!C160 -> 5811.47 | O63: ='48 QNAS'!B160 -> 278950.4 | P63: ='36 QNAS'!C160 -> 6867.02 | Q63: ='36 QNAS'!B160 -> 247212.8 | R63: ='24 QNAS'!C160 -> 8978.13 | S63: ='24 QNAS'!B160 -> 215475.2
A64: 103000 | B64: ='72 QNAS'!C111 -> 3222.76 | C64: ='72 QNAS'!B111 -> 232038.4 | D64: ='48 QNAS'!C111 -> 3938.03 | E64: ='48 QNAS'!B111 -> 189025.6 | F64: ='36 QNAS'!C111 -> 4653.31 | G64: ='36 QNAS'!B111 -> 167519.2 | H64: ='24 QNAS'!C111 -> 6083.87 | I64: ='24 QNAS'!B111 -> 146012.8 | K64: 153000 | L64: ='72 QNAS'!C161 -> 4787.2 | M64: ='72 QNAS'!B161 -> 344678.4 | N64: ='48 QNAS'!C161 -> 5849.7 | O64: ='48 QNAS'!B161 -> 280785.6 | P64: ='36 QNAS'!C161 -> 6912.2 | Q64: ='36 QNAS'!B161 -> 248839.2 | R64: ='24 QNAS'!C161 -> 9037.2 | S64: ='24 QNAS'!B161 -> 216892.8
A65: 104000 | B65: ='72 QNAS'!C112 -> 3254.04 | C65: ='72 QNAS'!B112 -> 234291.2 | D65: ='48 QNAS'!C112 -> 3976.27 | E65: ='48 QNAS'!B112 -> 190860.8 | F65: ='36 QNAS'!C112 -> 4698.49 | G65: ='36 QNAS'!B112 -> 169145.6 | H65: ='24 QNAS'!C112 -> 6142.93 | I65: ='24 QNAS'!B112 -> 147430.4 | K65: 154000 | L65: ='72 QNAS'!C162 -> 4818.49 | M65: ='72 QNAS'!B162 -> 346931.2 | N65: ='48 QNAS'!C162 -> 5887.93 | O65: ='48 QNAS'!B162 -> 282620.8 | P65: ='36 QNAS'!C162 -> 6957.38 | Q65: ='36 QNAS'!B162 -> 250465.6 | R65: ='24 QNAS'!C162 -> 9096.27 | S65: ='24 QNAS'!B162 -> 218310.4
A66: 105000 | B66: ='72 QNAS'!C113 -> 3285.33 | C66: ='72 QNAS'!B113 -> 236544 | D66: ='48 QNAS'!C113 -> 4014.5 | E66: ='48 QNAS'!B113 -> 192696 | F66: ='36 QNAS'!C113 -> 4743.67 | G66: ='36 QNAS'!B113 -> 170772 | H66: ='24 QNAS'!C113 -> 6202 | I66: ='24 QNAS'!B113 -> 148848 | K66: 155000 | L66: ='72 QNAS'!C163 -> 4849.78 | M66: ='72 QNAS'!B163 -> 349184 | N66: ='48 QNAS'!C163 -> 5926.17 | O66: ='48 QNAS'!B163 -> 284456 | P66: ='36 QNAS'!C163 -> 7002.56 | Q66: ='36 QNAS'!B163 -> 252092 | R66: ='24 QNAS'!C163 -> 9155.33 | S66: ='24 QNAS'!B163 -> 219728
A67: 106000 | B67: ='72 QNAS'!C114 -> 3316.62 | C67: ='72 QNAS'!B114 -> 238796.8 | D67: ='48 QNAS'!C114 -> 4052.73 | E67: ='48 QNAS'!B114 -> 194531.2 | F67: ='36 QNAS'!C114 -> 4788.84 | G67: ='36 QNAS'!B114 -> 172398.4 | H67: ='24 QNAS'!C114 -> 6261.07 | I67: ='24 QNAS'!B114 -> 150265.6 | K67: 156000 | L67: ='72 QNAS'!C164 -> 4881.07 | M67: ='72 QNAS'!B164 -> 351436.8 | N67: ='48 QNAS'!C164 -> 5964.4 | O67: ='48 QNAS'!B164 -> 286291.2 | P67: ='36 QNAS'!C164 -> 7047.73 | Q67: ='36 QNAS'!B164 -> 253718.4 | R67: ='24 QNAS'!C164 -> 9214.4 | S67: ='24 QNAS'!B164 -> 221145.6
A68: 107000 | B68: ='72 QNAS'!C115 -> 3347.91 | C68: ='72 QNAS'!B115 -> 241049.6 | D68: ='48 QNAS'!C115 -> 4090.97 | E68: ='48 QNAS'!B115 -> 196366.4 | F68: ='36 QNAS'!C115 -> 4834.02 | G68: ='36 QNAS'!B115 -> 174024.8 | H68: ='24 QNAS'!C115 -> 6320.13 | I68: ='24 QNAS'!B115 -> 151683.2 | K68: 157000 | L68: ='72 QNAS'!C165 -> 4912.36 | M68: ='72 QNAS'!B165 -> 353689.6 | N68: ='48 QNAS'!C165 -> 6002.63 | O68: ='48 QNAS'!B165 -> 288126.4 | P68: ='36 QNAS'!C165 -> 7092.91 | Q68: ='36 QNAS'!B165 -> 255344.8 | R68: ='24 QNAS'!C165 -> 9273.47 | S68: ='24 QNAS'!B165 -> 222563.2
A69: 108000 | B69: ='72 QNAS'!C116 -> 3379.2 | C69: ='72 QNAS'!B116 -> 243302.4 | D69: ='48 QNAS'!C116 -> 4129.2 | E69: ='48 QNAS'!B116 -> 198201.6 | F69: ='36 QNAS'!C116 -> 4879.2 | G69: ='36 QNAS'!B116 -> 175651.2 | H69: ='24 QNAS'!C116 -> 6379.2 | I69: ='24 QNAS'!B116 -> 153100.8 | K69: 158000 | L69: ='72 QNAS'!C166 -> 4943.64 | M69: ='72 QNAS'!B166 -> 355942.4 | N69: ='48 QNAS'!C166 -> 6040.87 | O69: ='48 QNAS'!B166 -> 289961.6 | P69: ='36 QNAS'!C166 -> 7138.09 | Q69: ='36 QNAS'!B166 -> 256971.2 | R69: ='24 QNAS'!C166 -> 9332.53 | S69: ='24 QNAS'!B166 -> 223980.8
A70: 109000 | B70: ='72 QNAS'!C117 -> 3410.49 | C70: ='72 QNAS'!B117 -> 245555.2 | D70: ='48 QNAS'!C117 -> 4167.43 | E70: ='48 QNAS'!B117 -> 200036.8 | F70: ='36 QNAS'!C117 -> 4924.38 | G70: ='36 QNAS'!B117 -> 177277.6 | H70: ='24 QNAS'!C117 -> 6438.27 | I70: ='24 QNAS'!B117 -> 154518.4 | K70: 159000 | L70: ='72 QNAS'!C167 -> 4974.93 | M70: ='72 QNAS'!B167 -> 358195.2 | N70: ='48 QNAS'!C167 -> 6079.1 | O70: ='48 QNAS'!B167 -> 291796.8 | P70: ='36 QNAS'!C167 -> 7183.27 | Q70: ='36 QNAS'!B167 -> 258597.6 | R70: ='24 QNAS'!C167 -> 9391.6 | S70: ='24 QNAS'!B167 -> 225398.4
A71: 110000 | B71: ='72 QNAS'!C118 -> 3441.78 | C71: ='72 QNAS'!B118 -> 247808 | D71: ='48 QNAS'!C118 -> 4205.67 | E71: ='48 QNAS'!B118 -> 201872 | F71: ='36 QNAS'!C118 -> 4969.56 | G71: ='36 QNAS'!B118 -> 178904 | H71: ='24 QNAS'!C118 -> 6497.33 | I71: ='24 QNAS'!B118 -> 155936 | K71: 160000 | L71: ='72 QNAS'!C168 -> 5006.22 | M71: ='72 QNAS'!B168 -> 360448 | N71: ='48 QNAS'!C168 -> 6117.33 | O71: ='48 QNAS'!B168 -> 293632 | P71: ='36 QNAS'!C168 -> 7228.44 | Q71: ='36 QNAS'!B168 -> 260224 | R71: ='24 QNAS'!C168 -> 9450.67 | S71: ='24 QNAS'!B168 -> 226816
A72: 111000 | B72: ='72 QNAS'!C119 -> 3473.07 | C72: ='72 QNAS'!B119 -> 250060.8 | D72: ='48 QNAS'!C119 -> 4243.9 | E72: ='48 QNAS'!B119 -> 203707.2 | F72: ='36 QNAS'!C119 -> 5014.73 | G72: ='36 QNAS'!B119 -> 180530.4 | H72: ='24 QNAS'!C119 -> 6556.4 | I72: ='24 QNAS'!B119 -> 157353.6 | K72: 161000 | L72: ='72 QNAS'!C169 -> 5037.51 | M72: ='72 QNAS'!B169 -> 362700.8 | N72: ='48 QNAS'!C169 -> 6155.57 | O72: ='48 QNAS'!B169 -> 295467.2 | P72: ='36 QNAS'!C169 -> 7273.62 | Q72: ='36 QNAS'!B169 -> 261850.4 | R72: ='24 QNAS'!C169 -> 9509.73 | S72: ='24 QNAS'!B169 -> 228233.6
A73: 112000 | B73: ='72 QNAS'!C120 -> 3504.36 | C73: ='72 QNAS'!B120 -> 252313.6 | D73: ='48 QNAS'!C120 -> 4282.13 | E73: ='48 QNAS'!B120 -> 205542.4 | F73: ='36 QNAS'!C120 -> 5059.91 | G73: ='36 QNAS'!B120 -> 182156.8 | H73: ='24 QNAS'!C120 -> 6615.47 | I73: ='24 QNAS'!B120 -> 158771.2 | K73: 162000 | L73: ='72 QNAS'!C170 -> 5068.8 | M73: ='72 QNAS'!B170 -> 364953.6 | N73: ='48 QNAS'!C170 -> 6193.8 | O73: ='48 QNAS'!B170 -> 297302.4 | P73: ='36 QNAS'!C170 -> 7318.8 | Q73: ='36 QNAS'!B170 -> 263476.8 | R73: ='24 QNAS'!C170 -> 9568.8 | S73: ='24 QNAS'!B170 -> 229651.2
A74: 113000 | B74: ='72 QNAS'!C121 -> 3535.64 | C74: ='72 QNAS'!B121 -> 254566.4 | D74: ='48 QNAS'!C121 -> 4320.37 | E74: ='48 QNAS'!B121 -> 207377.6 | F74: ='36 QNAS'!C121 -> 5105.09 | G74: ='36 QNAS'!B121 -> 183783.2 | H74: ='24 QNAS'!C121 -> 6674.53 | I74: ='24 QNAS'!B121 -> 160188.8 | K74: 163000 | L74: ='72 QNAS'!C171 -> 5100.09 | M74: ='72 QNAS'!B171 -> 367206.4 | N74: ='48 QNAS'!C171 -> 6232.03 | O74: ='48 QNAS'!B171 -> 299137.6 | P74: ='36 QNAS'!C171 -> 7363.98 | Q74: ='36 QNAS'!B171 -> 265103.2 | R74: ='24 QNAS'!C171 -> 9627.87 | S74: ='24 QNAS'!B171 -> 231068.8
... A112: 151000 | B112: ='72 QNAS'!C159 -> 4724.62 | C112: ='72 QNAS'!B159 -> 340172.8 | D112: ='48 QNAS'!C159 -> 5773.23 | E112: ='48 QNAS'!B159 -> 277115.2 | F112: ='36 QNAS'!C159 -> 6821.84 | G112: ='36 QNAS'!B159 -> 245586.4 | H112: ='24 QNAS'!C159 -> 8919.07 | I112: ='24 QNAS'!B159 -> 214057.6 | K112: 201000 | L112: ='72 QNAS'!C209 -> 6289.07 | M112: ='72 QNAS'!B209 -> 452812.8 | N112: ='48 QNAS'!C209 -> 7684.9 | O112: ='48 QNAS'!B209 -> 368875.2 | P112: ='36 QNAS'!C209 -> 9080.73 | Q112: ='36 QNAS'!B209 -> 326906.4 | R112: ='24 QNAS'!C209 -> 11872.4 | S112: ='24 QNAS'!B209 -> 284937.6
A115: Tasa Anual | B115: =B1 -> #REF! | D115: =D1 -> #REF! | F115: =F1 -> #REF! | H115: =H1 -> #REF! | K115: Tasa Anual | L115: =L1 -> #REF! | N115: =N1 -> #REF! | P115: =P1 -> #REF! | R115: =R1 -> #REF!
A116: Tasa Mensual | B116: ='tablas Guia'!B2 -> #REF! | D116: ='tablas Guia'!D2 -> #REF! | F116: ='tablas Guia'!F2 -> #REF! | H116: ='tablas Guia'!H2 -> #REF! | K116: Tasa Mensual | L116: =L2 -> #REF! | N116: =N2 -> #REF! | P116: =P2 -> #REF! | R116: =R2 -> #REF!
A117: CAT | B117: =B3 -> 0.7439 | D117: =D3 -> 0.7983 | F117: =F3 -> 0.8298 | H117: =H3 -> 0.8609 | K117: CAT | L117: =L3 -> 0.7439 | N117: =N3 -> 0.7983 | P117: =P3 -> 0.8298 | R117: =R3 -> 0.8609
...
